<?xml version="1.0"?>
<robot xmlns:xacro="http://ros.org/wiki/xacro" xmlns:gz="http://gazebosim.org/schema">

  <!--################################### Define properties ####################################-->
  <xacro:property name="rear_wheel_mass" value="2.21599675699028" />
  <xacro:property name="rear_wheel_ixx" value="0.00879190219168737" />
  <xacro:property name="rear_wheel_iyy" value="0.00879189675059079" />
  <xacro:property name="rear_wheel_izz" value="0.016563983880111" />
  <xacro:property name="rear_wheel_color" value="0.1 0.1 0.1 1" />
  <xacro:property name="rear_wheel_origin_x" value="-0.415" />
  <xacro:property name="rear_wheel_origin_y" value="0.3738" />
  <xacro:property name="rear_wheel_origin_z" value="0.02" />
  <xacro:property name="rear_wheel_axis_z" value="-1.0" />
  <!--##########################################################################################-->

  <!--#######################################-Macros-##########################################-->
  <xacro:macro name="rear_wheel" params="side r_reflect">

    <link name="wheel_r${side}_link">
      <xacro:default_inertial
        mass="${rear_wheel_mass}"
        ixx="${rear_wheel_ixx}" ixy="0" ixz="0"
        iyy="${rear_wheel_iyy}" iyz="0" izz="${rear_wheel_izz}"
        xyz="0 0 0"/>
      <xacro:mesh_visual_collision color="${rear_wheel_color}" mesh="wheel_r${side}_link.STL"/>  
    </link>

    <joint name="wheel_r${side}_joint" type="continuous">
      <origin xyz="${rear_wheel_origin_x} ${r_reflect*rear_wheel_origin_y} ${rear_wheel_origin_z}" rpy="${r_reflect*(PI/2)} 0 0"/>
      <parent link="base_link"/>
      <child link="wheel_r${side}_link"/>
      <axis xyz="0 0 ${rear_wheel_axis_z*r_reflect}"/>
    </joint>

    <gazebo reference='wheel_r${side}_link'>
      <collision>
        <surface>
          <friction>
            <ode>
              <fdir1 gz:expressed_in="base_footprint">1 ${r_reflect} 0</fdir1>
              <mu>1.5</mu>
              <mu2>0.0</mu2>
            </ode>
          </friction>
        </surface>
      </collision>
      <visual>
          <material>
              <ambient>0 0 0 1.0</ambient>
              <diffuse>0 0 0 1.0</diffuse>
              <specular>0.2 0.2 0.2 1.0</specular>
              <emissive>0.0 0.0 0.0 0.0</emissive>
          </material>
      </visual>
    </gazebo>

  </xacro:macro>
  <!--##########################################################################################-->

</robot>
